<sdf version='1.7'>
  <model name='virtual_robot'>
    <link name='car_1_base_link'>
      <inertial>
        <pose>0.146975 1.2e-05 0.054895 0 -0 0</pose>
        <mass>4.13003</mass>
        <inertia>
          <ixx>0.0140204</ixx>
          <ixy>0.000114667</ixy>
          <ixz>0.00059421</ixz>
          <iyy>0.05386</iyy>
          <iyz>-0.000181492</iyz>
          <izz>0.0589678</izz>
        </inertia>
      </inertial>
      <collision name='car_1_base_link_fixed_joint_lump__car_1_laser_collision'>
        <pose>0.125 0 0.205 0 -0 0</pose>
        <geometry>
          <box>
            <size>0.1 0.1 0.1</size>
          </box>
        </geometry>
        <surface>
          <contact>
            <ode/>
          </contact>
          <friction>
            <ode/>
          </friction>
        </surface>
      </collision>
      <collision name='car_1_base_link_fixed_joint_lump__car_1_link_collision_1'>
        <pose>0.39 0 0.325 0 -0 0</pose>
        <geometry>
          <box>
            <size>0.033 0.175 0.03</size>
          </box>
        </geometry>
      </collision>
      <visual name='car_1_base_link_fixed_joint_lump__car_1_chassis_visual'>
        <pose>0.46 -0.135 -0.13 1.57 0 3.14</pose>
        <geometry>
          <mesh>
            <scale>0.00099 0.000938 0.000938</scale>
            <uri>model://f1tenth-sim/urdf/meshes/chassis.stl</uri>
          </mesh>
        </geometry>
        <material>
          <script>
            <name>Gazebo/Blue</name>
            <uri>file://media/materials/scripts/gazebo.material</uri>
          </script>
        </material>
      </visual>
      <visual name='car_1_base_link_fixed_joint_lump__car_1_laser_visual_1'>
        <pose>0.125 0 0.205 0 -0 0</pose>
        <geometry>
          <mesh>
            <scale>1 1 1</scale>
            <uri>model://f1tenth-sim/urdf/meshes/hokuyo.stl</uri>
          </mesh>
        </geometry>
        <material>
          <script>
            <name>Gazebo/Grey</name>
            <uri>file://media/materials/scripts/gazebo.material</uri>
          </script>
        </material>
      </visual>
      <visual name='car_1_base_link_fixed_joint_lump__car_1_link_visual_2'>
        <pose>0.39 0 0.1 0 -0 0</pose>
        <geometry>
          <box>
            <size>0.033 0.175 0.03</size>
          </box>
        </geometry>
      </visual>
      <velocity_decay/>
      <velocity_decay/>
      <sensor name='car_1_hokuyo_sensor' type='ray'>
        <visualize>0</visualize>
        <update_rate>40</update_rate>
        <ray>
          <scan>
            <horizontal>
              <samples>1081</samples>
              <resolution>1</resolution>
              <min_angle>-2.35619</min_angle>
              <max_angle>2.35619</max_angle>
            </horizontal>
          </scan>
          <range>
            <min>0.1</min>
            <max>30</max>
            <resolution>0.01</resolution>
          </range>
          <noise>
            <mean>0</mean>
            <stddev>0.01</stddev>
            <type>gaussian</type>
          </noise>
        </ray>
        <plugin name='gazebo_ros_hokuyo_controller' filename='libgazebo_ros_laser.so'>
          <topicName>/car_1/scan</topicName>
          <frameName>car_1_laser</frameName>
        </plugin>
        <pose>0.125 0 0.205 0 -0 0</pose>
      </sensor>
      <gravity>1</gravity>
      <velocity_decay/>
      <sensor name='car_1_left_sensor' type='camera'>
        <update_rate>30</update_rate>
        <camera name='front_camera'>
          <horizontal_fov>1.74</horizontal_fov>
          <image>
            <width>1920</width>
            <height>1080</height>
            <format>B8G8R8</format>
          </image>
          <clip>
            <near>0.02</near>
            <far>300</far>
          </clip>
          <noise>
            <type>gaussian</type>
            <mean>0</mean>
            <stddev>0.007</stddev>
          </noise>
        </camera>
        <plugin name='camera_controller' filename='libgazebo_ros_camera.so'>
          <alwaysOn>1</alwaysOn>
          <updateRate>30.0</updateRate>
          <cameraName>/car_1/camera</cameraName>
          <imageTopicName>image</imageTopicName>
          <cameraInfoTopicName>rgb/camera_info</cameraInfoTopicName>
          <frameName>car_1_camera_link</frameName>
          <hackBaseline>0</hackBaseline>
          <distortionK1>0.0</distortionK1>
          <distortionK2>0.0</distortionK2>
          <distortionK3>0.0</distortionK3>
          <distortionT1>0.0</distortionT1>
          <distortionT2>0.0</distortionT2>
        </plugin>
        <pose>-2.11 1.5 1.825 0 0.57 -0.57</pose>
      </sensor>
    </link>
    <joint name='car_1_left_rear_wheel_joint' type='revolute'>
      <pose relative_to='car_1_base_link'>0 0.1 0.05 1.5708 -0 0</pose>
      <parent>car_1_base_link</parent>
      <child>car_1_left_rear_wheel</child>
      <axis>
        <xyz>0 0 -1</xyz>
        <limit>
          <lower>-1e+16</lower>
          <upper>1e+16</upper>
        </limit>
        <dynamics>
          <spring_reference>0</spring_reference>
          <spring_stiffness>0</spring_stiffness>
        </dynamics>
      </axis>
    </joint>
    <link name='car_1_left_rear_wheel'>
      <pose relative_to='car_1_left_rear_wheel_joint'>0 0 0 0 -0 0</pose>
      <inertial>
        <pose>0 0 -0.0225 0 -0 0</pose>
        <mass>0.34055</mass>
        <inertia>
          <ixx>0.00026046</ixx>
          <ixy>0</ixy>
          <ixz>0</ixz>
          <iyy>0.00026046</iyy>
          <iyz>0</iyz>
          <izz>0.00041226</izz>
        </inertia>
      </inertial>
      <collision name='car_1_left_rear_wheel_collision'>
        <pose>0 0 -0.0225 0 -0 0</pose>
        <geometry>
          <cylinder>
            <length>0.045</length>
            <radius>0.05</radius>
          </cylinder>
        </geometry>
        <surface>
          <contact>
            <ode>
              <kp>1e+07</kp>
              <kd>1</kd>
            </ode>
          </contact>
          <friction>
            <ode>
              <mu>1</mu>
              <mu2>1</mu2>
              <fdir1>1 0 0</fdir1>
            </ode>
          </friction>
        </surface>
      </collision>
      <visual name='car_1_left_rear_wheel_visual'>
        <pose>0 0 0 0 -0 0</pose>
        <geometry>
          <mesh>
            <scale>1 1 1</scale>
            <uri>model://f1tenth-sim/urdf/meshes/left_wheel.stl</uri>
          </mesh>
        </geometry>
        <material>
          <script>
            <name>Gazebo/Black</name>
            <uri>file://media/materials/scripts/gazebo.material</uri>
          </script>
        </material>
      </visual>
      <gravity>1</gravity>
      <velocity_decay/>
    </link>
    <joint name='car_1_left_steering_hinge_joint' type='revolute'>
      <pose relative_to='car_1_base_link'>0.325 0.1 0.05 3.14159 1.57079 3.14159</pose>
      <parent>car_1_base_link</parent>
      <child>car_1_left_steering_hinge</child>
      <axis>
        <xyz>-1 0 0</xyz>
        <limit>
          <lower>-1</lower>
          <upper>1</upper>
          <effort>10</effort>
          <velocity>100</velocity>
        </limit>
        <dynamics>
          <spring_reference>0</spring_reference>
          <spring_stiffness>0</spring_stiffness>
        </dynamics>
      </axis>
    </joint>
    <link name='car_1_left_steering_hinge'>
      <pose relative_to='car_1_left_steering_hinge_joint'>0 0 0 0 -0 0</pose>
      <inertial>
        <pose>0 0 0 0 -0 0</pose>
        <mass>0.1</mass>
        <inertia>
          <ixx>4e-06</ixx>
          <ixy>0</ixy>
          <ixz>0</ixz>
          <iyy>4e-06</iyy>
          <iyz>0</iyz>
          <izz>4e-06</izz>
        </inertia>
      </inertial>
      <visual name='car_1_left_steering_hinge_visual'>
        <pose>0 0 0 0 -0 0</pose>
        <geometry>
          <mesh>
            <scale>1 1 1</scale>
            <uri>model://f1tenth-sim/urdf/meshes/hinge.stl</uri>
          </mesh>
        </geometry>
      </visual>
    </link>
    <joint name='car_1_left_front_wheel_joint' type='revolute'>
      <pose relative_to='car_1_left_steering_hinge'>0 0 0 1.5708 -0 0</pose>
      <parent>car_1_left_steering_hinge</parent>
      <child>car_1_left_front_wheel</child>
      <axis>
        <xyz>0 0 -1</xyz>
        <limit>
          <lower>-1e+16</lower>
          <upper>1e+16</upper>
        </limit>
        <dynamics>
          <spring_reference>0</spring_reference>
          <spring_stiffness>0</spring_stiffness>
        </dynamics>
      </axis>
    </joint>
    <link name='car_1_left_front_wheel'>
      <pose relative_to='car_1_left_front_wheel_joint'>0 0 0 0 -0 0</pose>
      <inertial>
        <pose>0 0 -0.0225 0 -0 0</pose>
        <mass>0.34055</mass>
        <inertia>
          <ixx>0.00026046</ixx>
          <ixy>0</ixy>
          <ixz>0</ixz>
          <iyy>0.00026046</iyy>
          <iyz>0</iyz>
          <izz>0.00041226</izz>
        </inertia>
      </inertial>
      <collision name='car_1_left_front_wheel_collision'>
        <pose>0 0 -0.0225 0 -0 0</pose>
        <geometry>
          <cylinder>
            <length>0.045</length>
            <radius>0.05</radius>
          </cylinder>
        </geometry>
        <surface>
          <contact>
            <ode>
              <kp>1e+07</kp>
              <kd>1</kd>
            </ode>
          </contact>
          <friction>
            <ode>
              <mu>1</mu>
              <mu2>1</mu2>
              <fdir1>0 0 1</fdir1>
            </ode>
          </friction>
        </surface>
      </collision>
      <visual name='car_1_left_front_wheel_visual'>
        <pose>0 0 0 0 -0 0</pose>
        <geometry>
          <mesh>
            <scale>1 1 1</scale>
            <uri>model://f1tenth-sim/urdf/meshes/left_wheel.stl</uri>
          </mesh>
        </geometry>
        <material>
          <script>
            <name>Gazebo/Black</name>
            <uri>file://media/materials/scripts/gazebo.material</uri>
          </script>
        </material>
      </visual>
      <gravity>1</gravity>
      <velocity_decay/>
    </link>
    <joint name='car_1_right_rear_wheel_joint' type='revolute'>
      <pose relative_to='car_1_base_link'>0 -0.1 0.05 1.5708 -0 0</pose>
      <parent>car_1_base_link</parent>
      <child>car_1_right_rear_wheel</child>
      <axis>
        <xyz>0 0 -1</xyz>
        <limit>
          <lower>-1e+16</lower>
          <upper>1e+16</upper>
        </limit>
        <dynamics>
          <spring_reference>0</spring_reference>
          <spring_stiffness>0</spring_stiffness>
        </dynamics>
      </axis>
    </joint>
    <link name='car_1_right_rear_wheel'>
      <pose relative_to='car_1_right_rear_wheel_joint'>0 0 0 0 -0 0</pose>
      <inertial>
        <pose>0 0 0.0225 0 -0 0</pose>
        <mass>0.34055</mass>
        <inertia>
          <ixx>0.00026046</ixx>
          <ixy>0</ixy>
          <ixz>0</ixz>
          <iyy>0.00026046</iyy>
          <iyz>0</iyz>
          <izz>0.00041226</izz>
        </inertia>
      </inertial>
      <collision name='car_1_right_rear_wheel_collision'>
        <pose>0 0 0.0225 0 -0 0</pose>
        <geometry>
          <cylinder>
            <length>0.045</length>
            <radius>0.05</radius>
          </cylinder>
        </geometry>
        <surface>
          <contact>
            <ode>
              <kp>1e+07</kp>
              <kd>1</kd>
            </ode>
          </contact>
          <friction>
            <ode>
              <mu>1</mu>
              <mu2>1</mu2>
              <fdir1>1 0 0</fdir1>
            </ode>
          </friction>
        </surface>
      </collision>
      <visual name='car_1_right_rear_wheel_visual'>
        <pose>0 0 0 0 -0 0</pose>
        <geometry>
          <mesh>
            <scale>1 1 1</scale>
            <uri>model://f1tenth-sim/urdf/meshes/right_wheel.stl</uri>
          </mesh>
        </geometry>
        <material>
          <script>
            <name>Gazebo/Black</name>
            <uri>file://media/materials/scripts/gazebo.material</uri>
          </script>
        </material>
      </visual>
      <gravity>1</gravity>
      <velocity_decay/>
    </link>
    <joint name='car_1_right_steering_hinge_joint' type='revolute'>
      <pose relative_to='car_1_base_link'>0.325 -0.1 0.05 3.14159 1.57079 3.14159</pose>
      <parent>car_1_base_link</parent>
      <child>car_1_right_steering_hinge</child>
      <axis>
        <xyz>-1 0 0</xyz>
        <limit>
          <lower>-1e+16</lower>
          <upper>1e+16</upper>
        </limit>
        <dynamics>
          <spring_reference>0</spring_reference>
          <spring_stiffness>0</spring_stiffness>
        </dynamics>
      </axis>
    </joint>
    <link name='car_1_right_steering_hinge'>
      <pose relative_to='car_1_right_steering_hinge_joint'>0 0 0 0 -0 0</pose>
      <inertial>
        <pose>0 0 0 0 -0 0</pose>
        <mass>0.1</mass>
        <inertia>
          <ixx>4e-06</ixx>
          <ixy>0</ixy>
          <ixz>0</ixz>
          <iyy>4e-06</iyy>
          <iyz>0</iyz>
          <izz>4e-06</izz>
        </inertia>
      </inertial>
      <visual name='car_1_right_steering_hinge_visual'>
        <pose>0 0 0 0 -0 0</pose>
        <geometry>
          <mesh>
            <scale>1 1 1</scale>
            <uri>model://f1tenth-sim/urdf/meshes/hinge.stl</uri>
          </mesh>
        </geometry>
      </visual>
    </link>
    <joint name='car_1_right_front_wheel_joint' type='revolute'>
      <pose relative_to='car_1_right_steering_hinge'>0 0 0 1.5708 -0 0</pose>
      <parent>car_1_right_steering_hinge</parent>
      <child>car_1_right_front_wheel</child>
      <axis>
        <xyz>0 0 -1</xyz>
        <limit>
          <lower>-1e+16</lower>
          <upper>1e+16</upper>
        </limit>
        <dynamics>
          <spring_reference>0</spring_reference>
          <spring_stiffness>0</spring_stiffness>
        </dynamics>
      </axis>
    </joint>
    <link name='car_1_right_front_wheel'>
      <pose relative_to='car_1_right_front_wheel_joint'>0 0 0 0 -0 0</pose>
      <inertial>
        <pose>0 0 0.0225 0 -0 0</pose>
        <mass>0.34055</mass>
        <inertia>
          <ixx>0.00026046</ixx>
          <ixy>0</ixy>
          <ixz>0</ixz>
          <iyy>0.00026046</iyy>
          <iyz>0</iyz>
          <izz>0.00041226</izz>
        </inertia>
      </inertial>
      <collision name='car_1_right_front_wheel_collision'>
        <pose>0 0 0.0225 0 -0 0</pose>
        <geometry>
          <cylinder>
            <length>0.045</length>
            <radius>0.05</radius>
          </cylinder>
        </geometry>
        <surface>
          <contact>
            <ode>
              <kp>1e+07</kp>
              <kd>1</kd>
            </ode>
          </contact>
          <friction>
            <ode>
              <mu>1</mu>
              <mu2>1</mu2>
              <fdir1>0 0 1</fdir1>
            </ode>
          </friction>
        </surface>
      </collision>
      <visual name='car_1_right_front_wheel_visual'>
        <pose>0 0 0 0 -0 0</pose>
        <geometry>
          <mesh>
            <scale>1 1 1</scale>
            <uri>model://f1tenth-sim/urdf/meshes/right_wheel.stl</uri>
          </mesh>
        </geometry>
        <material>
          <script>
            <name>Gazebo/Black</name>
            <uri>file://media/materials/scripts/gazebo.material</uri>
          </script>
        </material>
      </visual>
      <gravity>1</gravity>
      <velocity_decay/>
    </link>
    <plugin name='gazebo_ros_control' filename='libgazebo_ros_control.so'>
      <robotNamespace>/car_1</robotNamespace>
      <robotSimType>gazebo_ros_control/DefaultRobotHWSim</robotSimType>
    </plugin>
    <static>0</static>
    <plugin name='p3d_base_controller' filename='libgazebo_ros_p3d.so'>
      <alwaysOn>1</alwaysOn>
      <updateRate>50.0</updateRate>
      <bodyName>car_1_base_link</bodyName>
      <topicName>/car_1/ground_truth</topicName>
      <gaussianNoise>0.01</gaussianNoise>
      <frameName>world</frameName>
      <xyzOffsets>0 0 0</xyzOffsets>
      <rpyOffsets>0 0 0</rpyOffsets>
    </plugin>
  </model>
</sdf>
