<?xml version="1.0" encoding="utf-8"?>
<!-- =================================================================================== -->
<!-- |    This document was autogenerated by xacro from two_wheel_robot.xacro.xml      | -->
<!-- |    EDITING THIS FILE BY HAND IS NOT RECOMMENDED                                 | -->
<!-- =================================================================================== -->
<robot name="jetbot_model">
  <!-- inertial parameter macros -->
  <!-- Now the robot description-->
  <link name="chassis">
    <origin rpy="0 0 0" xyz="0 0 .1"/>
    <collision name="collision">
      <geometry>
        <box size=".4 .2 .1"/>
      </geometry>
    </collision>
    <visual name="visual">
      <geometry>
        <box size=".4 .2 .1"/>
      </geometry>
    </visual>
    <collision name="caster-collision">
      <origin rpy="0 0 0" xyz="-0.15 0 -0.05"/>
      <geometry>
        <sphere radius=".05"/>
      </geometry>
      <!--  <surface>
       <xacro:caster_surface/>
      </surface> -->
    </collision>
    <visual name="caster_visual">
      <origin rpy="0 0 0" xyz="-0.15 0 -0.05"/>
      <geometry>
        <sphere radius=".05"/>
      </geometry>
    </visual>
  </link>
  <link name="left_wheel">
    <origin rpy=" 0 1.5707 1.5707" xyz=" 0.1 0.13 0.1"/>
    <collision name="collision">
      <geometry>
        <cylinder length="0.05" radius="0.1"/>
      </geometry>
    </collision>
    <visual name="visual">
      <geometry>
        <cylinder length="0.05" radius="0.1"/>
      </geometry>
    </visual>
  </link>
  <link name="right_wheel">
    <origin rpy="0 1.5707 1.5707" xyz="0.1 -0.13 0.1"/>
    <collision name="collision">
      <geometry>
        <cylinder length="0.05" radius="0.1"/>
      </geometry>
    </collision>
    <visual name="visual">
      <geometry>
        <cylinder length="0.05" radius="0.1"/>
      </geometry>
    </visual>
  </link>
  <joint name="left_wheel_joint" type="revolute">
    <origin rpy="0 0 0" xyz="0 0 -0.03"/>
    <child link="left_wheel"/>
    <parent link="chassis"/>
    <axis xyz="0 1 0"/>
  </joint>
  <transmission name="car_1_left_wheel_transmission" type="SimpleTransmission">
    <type>transmission_interface/SimpleTransmission</type>
    <joint name="car_1_left_wheel_joint">
      <hardwareInterface>hardware_interface/EffortJointInterface</hardwareInterface>
    </joint>
    <actuator name="car_1_left_wheel_motor">
      <hardwareInterface>hardware_interface/EffortJointInterface</hardwareInterface>
      <mechanicalReduction>1</mechanicalReduction>
    </actuator>
  </transmission>
  <joint name="right_wheel_joint" type="revolute">
    <origin rpy="0 0 0" xyz="0 0 0.03"/>
    <child link="right_wheel"/>
    <parent link="chassis"/>
    <axis xyz="0 1 0"/>
  </joint>
  <transmission name="car_1_right_wheel_transmission" type="SimpleTransmission">
    <type>transmission_interface/SimpleTransmission</type>
    <joint name="car_1_right_wheel_joint">
      <hardwareInterface>hardware_interface/EffortJointInterface</hardwareInterface>
    </joint>
    <actuator name="car_1_right_wheel_motor">
      <hardwareInterface>hardware_interface/EffortJointInterface</hardwareInterface>
      <mechanicalReduction>1</mechanicalReduction>
    </actuator>
  </transmission>
</robot>
